
#######################################################################
# +-----------------------------------------------------------------+ #
# |                            BO4 object                           | #
# +-----------------------------------------------------------------+ #
#######################################################################

Author: NLBlackEagle

Description: No description given

SettingsMode: WriteWithoutComments


#######################################################################
# +-----------------------------------------------------------------+ #
# |                          Main settings                          | #
# +-----------------------------------------------------------------+ #
#######################################################################

FixedRotation: 

Frequency: 0

SpawnHeight: highestSolidBlock

UseCenterForHighestBlock: true

##############################
# Height Limits for the BO4. #
##############################

MinHeight: 0

MaxHeight: 255

InheritBO3: 

InheritBO3Rotation: NORTH

OverrideChildSettings: true

OverrideParentHeight: false

CanOverride: true

BranchFrequency: 0

BranchFrequencyGroup: 

MustBeBelowOther: false

MustBeInside: 

CannotBeInside: 

ReplacesBO3: 

MustBeInsideWorldBorders: false

CanSpawnOnWater: false

SpawnOnWaterOnly: false

SpawnUnderWater: false

SpawnAtWaterLevel: false

HeightOffset: 0

RemoveAir: false

ReplaceAbove: 

ReplaceBelow: 

ReplaceWithBiomeBlocks: false

ReplaceWithSurfaceBlock: GRASS

ReplaceWithGroundBlock: DIRT

ReplaceWithStoneBlock: STONE

SmoothRadius: 7

SmoothHeightOffset: 0

SmoothStartTop: true

SmoothStartWood: false

SmoothingSurfaceBlock: 

SmoothingGroundBlock: 

BO3Group: 

IsSpawnPoint: false

DoReplaceBlocks: true


#######################################################################
# +-----------------------------------------------------------------+ #
# |                              Blocks                             | #
# +-----------------------------------------------------------------+ #
#######################################################################

RandomBlock(-2,0,-2,SMOOTH_BRICK:0,40,SMOOTH_BRICK:1,20,SMOOTH_BRICK:2,30,SMOOTH_BRICK:0,100)
RandomBlock(-2,0,-1,SMOOTH_BRICK:0,40,SMOOTH_BRICK:1,20,SMOOTH_BRICK:2,30,SMOOTH_BRICK:0,100)
Block(-2,0,0,MONSTER_EGGS:1)
RandomBlock(-2,0,1,SMOOTH_BRICK:0,40,SMOOTH_BRICK:1,20,SMOOTH_BRICK:2,30,SMOOTH_BRICK:0,100)
Block(-2,0,2,MONSTER_EGGS:1)
RandomBlock(-2,0,3,SMOOTH_BRICK:0,40,SMOOTH_BRICK:1,20,SMOOTH_BRICK:2,30,SMOOTH_BRICK:0,100)
RandomBlock(-1,0,-2,SMOOTH_BRICK:0,40,SMOOTH_BRICK:1,20,SMOOTH_BRICK:2,30,SMOOTH_BRICK:0,100)
Block(-1,0,-1,MONSTER_EGGS:1)
RandomBlock(-1,0,0,SMOOTH_BRICK:0,40,SMOOTH_BRICK:1,20,SMOOTH_BRICK:2,30,SMOOTH_BRICK:0,100)
RandomBlock(-1,0,1,SMOOTH_BRICK:0,40,SMOOTH_BRICK:1,20,SMOOTH_BRICK:2,30,SMOOTH_BRICK:0,100)
Block(-1,0,2,MONSTER_EGGS:1)
RandomBlock(-1,0,3,SMOOTH_BRICK:0,40,SMOOTH_BRICK:1,20,SMOOTH_BRICK:2,30,SMOOTH_BRICK:0,100)
Block(-1,1,-1,FENCE:0)
Block(-1,1,0,BED_BLOCK:0)
Block(-1,1,1,BED_BLOCK:8)
Block(-1,1,2,FENCE:0)
Block(-1,2,-1,FENCE:0)
Block(-1,2,0,AIR:0)
Block(-1,2,1,AIR:0)
Block(-1,2,2,FENCE:0)
Block(-1,3,-1,FENCE:0)
Block(-1,3,0,AIR:0)
Block(-1,3,1,AIR:0)
Block(-1,3,2,FENCE:0)
Block(-1,4,-1,FENCE:0)
Block(-1,4,0,AIR:0)
Block(-1,4,1,AIR:0)
Block(-1,4,2,FENCE:0)
Block(-1,5,-1,WOOD:0)
Block(-1,5,0,WOOD:0)
Block(-1,5,1,WOOD:0)
Block(-1,5,2,WOOD:0)
RandomBlock(0,0,-2,SMOOTH_BRICK:0,40,SMOOTH_BRICK:1,20,SMOOTH_BRICK:2,30,SMOOTH_BRICK:0,100)
RandomBlock(0,0,-1,SMOOTH_BRICK:0,40,SMOOTH_BRICK:1,20,SMOOTH_BRICK:2,30,SMOOTH_BRICK:0,100)
Block(0,0,0,MONSTER_EGGS:1)
Block(0,0,1,MONSTER_EGGS:1)
Block(0,0,2,MONSTER_EGGS:1)
RandomBlock(0,0,3,SMOOTH_BRICK:0,40,SMOOTH_BRICK:1,20,SMOOTH_BRICK:2,30,SMOOTH_BRICK:0,100)
RandomBlock(0,1,-1,CHEST:3,../../../../Chests/Loot/junk_loot.nbt,20,CHEST:3../../../../Chests/Loot/rare_loot.nbt,5,CHEST:3,../../../../Chests/Loot/food_loot.nbt,30,CHEST:3,../../../../Chests/Loot/spawn_bonus_chest.nbt,50,CHEST:3,../../../../Chests/Loot/junk_loot.nbt,100)
Block(0,1,0,AIR:0)
Block(0,1,1,AIR:0)
Block(0,1,2,SKULL:1)
Block(0,2,-1,AIR:0)
Block(0,2,0,AIR:0)
Block(0,2,1,AIR:0)
Block(0,2,2,AIR:0)
Block(0,3,-1,AIR:0)
Block(0,3,0,AIR:0)
Block(0,3,1,AIR:0)
Block(0,3,2,AIR:0)
Block(0,4,-1,AIR:0)
Block(0,4,0,AIR:0)
Block(0,4,1,AIR:0)
Block(0,4,2,AIR:0)
Block(0,5,-1,FENCE:0)
Block(0,5,0,FENCE:0)
Block(0,5,1,FENCE:0)
Block(0,5,2,FENCE:0)
RandomBlock(1,0,-2,SMOOTH_BRICK:0,40,SMOOTH_BRICK:1,20,SMOOTH_BRICK:2,30,SMOOTH_BRICK:0,100)
RandomBlock(1,0,-1,SMOOTH_BRICK:0,40,SMOOTH_BRICK:1,20,SMOOTH_BRICK:2,30,SMOOTH_BRICK:0,100)
Block(1,0,0,MONSTER_EGGS:1)
RandomBlock(1,0,1,SMOOTH_BRICK:0,40,SMOOTH_BRICK:1,20,SMOOTH_BRICK:2,30,SMOOTH_BRICK:0,100)
RandomBlock(1,0,2,SMOOTH_BRICK:0,40,SMOOTH_BRICK:1,20,SMOOTH_BRICK:2,30,SMOOTH_BRICK:0,100)
RandomBlock(1,0,3,SMOOTH_BRICK:0,40,SMOOTH_BRICK:1,20,SMOOTH_BRICK:2,30,SMOOTH_BRICK:0,100)
Block(1,1,-1,WORKBENCH:0)
Block(1,1,0,AIR:0)
Block(1,1,1,AIR:0)
Block(1,1,2,LADDER:2)
Block(1,2,-1,AIR:0)
Block(1,2,0,AIR:0)
Block(1,2,1,AIR:0)
Block(1,2,2,LADDER:2)
Block(1,3,-1,AIR:0)
Block(1,3,0,AIR:0)
Block(1,3,1,AIR:0)
Block(1,3,2,LADDER:2)
Block(1,4,-1,AIR:0)
Block(1,4,0,AIR:0)
Block(1,4,1,AIR:0)
Block(1,4,2,LADDER:2)
Block(1,5,-1,FENCE:0)
Block(1,5,0,FENCE:0)
Block(1,5,1,FENCE:0)
Block(1,5,2,LADDER:2)
Block(1,6,2,LADDER:2)
Block(1,7,2,AIR:0)
RandomBlock(2,0,-2,SMOOTH_BRICK:0,40,SMOOTH_BRICK:1,20,SMOOTH_BRICK:2,30,SMOOTH_BRICK:0,100)
RandomBlock(2,0,-1,SMOOTH_BRICK:0,40,SMOOTH_BRICK:1,20,SMOOTH_BRICK:2,30,SMOOTH_BRICK:0,100)
RandomBlock(2,0,0,SMOOTH_BRICK:0,40,SMOOTH_BRICK:1,20,SMOOTH_BRICK:2,30,SMOOTH_BRICK:0,100)
RandomBlock(2,0,1,SMOOTH_BRICK:0,40,SMOOTH_BRICK:1,20,SMOOTH_BRICK:2,30,SMOOTH_BRICK:0,100)
Block(2,0,2,MONSTER_EGGS:1)
Block(2,0,3,MONSTER_EGGS:1)
Block(2,1,-1,FENCE:0)
Block(2,1,0,AIR:0)
Block(2,1,1,FURNACE:4)
Block(2,1,2,FENCE:0)
Block(2,2,-1,FENCE:0)
Block(2,2,0,AIR:0)
Block(2,2,1,AIR:0)
Block(2,2,2,FENCE:0)
Block(2,3,-1,FENCE:0)
Block(2,3,0,AIR:0)
Block(2,3,1,AIR:0)
Block(2,3,2,FENCE:0)
Block(2,4,-1,FENCE:0)
Block(2,4,0,AIR:0)
Block(2,4,1,AIR:0)
Block(2,4,2,FENCE:0)
Block(2,5,-1,WOOD:0)
Block(2,5,0,WOOD:0)
Block(2,5,1,WOOD:0)
Block(2,5,2,WOOD:0)
Block(3,0,-2,MONSTER_EGGS:1)
RandomBlock(3,0,-1,SMOOTH_BRICK:0,40,SMOOTH_BRICK:1,20,SMOOTH_BRICK:2,30,SMOOTH_BRICK:0,100)
RandomBlock(3,0,0,SMOOTH_BRICK:0,40,SMOOTH_BRICK:1,20,SMOOTH_BRICK:2,30,SMOOTH_BRICK:0,100)
RandomBlock(3,0,1,SMOOTH_BRICK:0,40,SMOOTH_BRICK:1,20,SMOOTH_BRICK:2,30,SMOOTH_BRICK:0,100)
RandomBlock(3,0,2,SMOOTH_BRICK:0,40,SMOOTH_BRICK:1,20,SMOOTH_BRICK:2,30,SMOOTH_BRICK:0,100)
RandomBlock(3,0,3,SMOOTH_BRICK:0,40,SMOOTH_BRICK:1,20,SMOOTH_BRICK:2,30,SMOOTH_BRICK:0,100)

#######################################################################
# +-----------------------------------------------------------------+ #
# |                             Branches                            | #
# +-----------------------------------------------------------------+ #
#######################################################################


#######################################################################
# +-----------------------------------------------------------------+ #
# |                             Entities                            | #
# +-----------------------------------------------------------------+ #
#######################################################################


#######################################################################
# +-----------------------------------------------------------------+ #
# |                            Particles                            | #
# +-----------------------------------------------------------------+ #
#######################################################################


#######################################################################
# +-----------------------------------------------------------------+ #
# |                             Spawners                            | #
# +-----------------------------------------------------------------+ #
#######################################################################


#######################################################################
# +-----------------------------------------------------------------+ #
# |                             ModData                             | #
# +-----------------------------------------------------------------+ #
#######################################################################

